<robot name="onshape">
<mujoco> <compiler fusestatic="false"/> </mujoco>
<link name="base">
<visual>
<origin xyz="-3.1995672897847401109e-16 -0.011036072480300897214 0.061999999999997092159" rpy="-6.1232620554170331445e-17 -1.3270634591222507219e-15 3.141592653589793116" />
<geometry>
<mesh filename="80i_v5.stl"/>
</geometry>
<material name="80i_v5_material">
<color rgba="0.61568627450980395466 0.81176470588235294379 0.92941176470588238168 1.0"/>
</material>
</visual>
<collision>
<origin xyz="-3.1995672897847401109e-16 -0.011036072480300897214 0.061999999999997092159" rpy="-6.1232620554170331445e-17 -1.3270634591222507219e-15 3.141592653589793116" />
<geometry>
<mesh filename="80i_v5.stl"/>
</geometry>
</collision>
<visual>
<origin xyz="-2.6194323913312536696e-16 -0.06093607248030450535 0.0019999999999976260726" rpy="1.1050188541972292746e-15 -6.1232339957368473871e-17 1.570796326794896558" />
<geometry>
<mesh filename="bati_erob80.stl"/>
</geometry>
<material name="bati_erob80_material">
<color rgba="0.47450980392156860699 0.35294117647058825815 0 1.0"/>
</material>
</visual>
<collision>
<origin xyz="-2.6194323913312536696e-16 -0.06093607248030450535 0.0019999999999976260726" rpy="1.1050188541972292746e-15 -6.1232339957368473871e-17 1.570796326794896558" />
<geometry>
<mesh filename="bati_erob80.stl"/>
</geometry>
</collision>
<inertial>
<origin xyz="8.5965635448629487496e-05 -0.028034738804695553266 0.056265374431782338993" rpy="0 0 0"/>
<mass value="2.1622242401867124428" />
<inertia ixx="0.0035409411921381614245" ixy="-1.0515353043570381151e-05"  ixz="-2.7906442063380420255e-06" iyy="0.0039888242306756532471" iyz="0.0005128653511785382247" izz="0.0035605287862095907903" />
</inertial>
</link>

<link name="bras1">
<visual>
<origin xyz="-0.12500000000000002776 3.6112633082917897775e-17 -0.016999999999999987343" rpy="-1.570796326794896558 -5.6920406751767812971e-33 1.9105225048187323569e-31" />
<geometry>
<mesh filename="bras1.stl"/>
</geometry>
<material name="bras1_material">
<color rgba="0.50196078431372548323 0.50196078431372548323 0.50196078431372548323 1.0"/>
</material>
</visual>
<collision>
<origin xyz="-0.12500000000000002776 3.6112633082917897775e-17 -0.016999999999999987343" rpy="-1.570796326794896558 -5.6920406751767812971e-33 1.9105225048187323569e-31" />
<geometry>
<mesh filename="bras1.stl"/>
</geometry>
</collision>
<inertial>
<origin xyz="-0.12500000000000002776 3.0283764591525292563e-17 -0.0075053453515004277946" rpy="0 0 0"/>
<mass value="1.6401618924870369209" />
<inertia ixx="0.0014573357440108673788" ixy="7.6494749519212727476e-33"  ixz="2.5929189483419927677e-35" iyy="0.014585620314120823632" iyz="1.0671161822730828223e-39" izz="0.015941817470486979724" />
</inertial>
</link>

<link name="segment2">
<visual>
<origin xyz="-1.3720819860076984538e-23 0 -0.027500000000004548584" rpy="-1.570796326794896558 4.3011950331735847137e-22 3.1415926535897926719" />
<geometry>
<mesh filename="bras2.stl"/>
</geometry>
<material name="bras2_material">
<color rgba="0.50196078431372548323 0.50196078431372548323 0.50196078431372548323 1.0"/>
</material>
</visual>
<collision>
<origin xyz="-1.3720819860076984538e-23 0 -0.027500000000004548584" rpy="-1.570796326794896558 4.3011950331735847137e-22 3.1415926535897926719" />
<geometry>
<mesh filename="bras2.stl"/>
</geometry>
</collision>
<visual>
<origin xyz="-2.4651903288156618919e-32 0 -0.059400000000008001955" rpy="1.570796326794896558 3.8947973516099456757e-38 3.6977854932234928379e-32" />
<geometry>
<mesh filename="80i_v5.stl"/>
</geometry>
<material name="80i_v5_material">
<color rgba="0.61568627450980395466 0.81176470588235294379 0.92941176470588238168 1.0"/>
</material>
</visual>
<collision>
<origin xyz="-2.4651903288156618919e-32 0 -0.059400000000008001955" rpy="1.570796326794896558 3.8947973516099456757e-38 3.6977854932234928379e-32" />
<geometry>
<mesh filename="80i_v5.stl"/>
</geometry>
</collision>
<visual>
<origin xyz="-3.0184188855770821741e-15 0.24999999999997304934 0.027499999999995250466" rpy="-3.1415926535897615857 -1.1129985391747538395e-14 3.1415926535897926719" />
<geometry>
<mesh filename="weight.stl"/>
</geometry>
<material name="weight_material">
<color rgba="0.30196078431372547213 0.30196078431372547213 0.30196078431372547213 1.0"/>
</material>
</visual>
<collision>
<origin xyz="-3.0184188855770821741e-15 0.24999999999997304934 0.027499999999995250466" rpy="-3.1415926535897615857 -1.1129985391747538395e-14 3.1415926535897926719" />
<geometry>
<mesh filename="weight.stl"/>
</geometry>
</collision>
<inertial>
<origin xyz="-1.4457205374984948181e-05 0.20443246054269068046 0.0023847587657958697026" rpy="0 0 0"/>
<mass value="12.857047818015505669" />
<inertia ixx="0.16793351668194522741" ixy="-3.9723997859661720213e-05"  ixz="-1.8840056687060193071e-05" iyy="0.064620563529158903116" iyz="-0.01983703796319074078" izz="0.2212259730717880124" />
</inertial>
</link>

<link name="end">
<inertial>
<origin xyz="0 0 0" rpy="0 0 0" />
<mass value="1e-9" />
<inertia ixx="0" ixy="0" ixz="0" iyy="0" iyz="0" izz="0" />
</inertial>
</link>
<joint name="end_frame" type="fixed">
<origin xyz="-2.9837244171328454876e-15 0.24999999999997310485 0.029999999999995238809" rpy="-1.1131317589294916161e-14 -3.1469101278800327038e-14 -1.5707963267948970021" />
<parent link="segment2" />
<child link="end" />
<axis xyz="0 0 0"/>
</joint>

<joint name="r2" type="revolute">
<origin xyz="-0.25000000000000005551 4.305149412567801521e-17 1.3877787807814456755e-17" rpy="-3.141592653589793116 -5.0387059551511362915e-28 -1.5707963267949036634" />
<parent link="bras1" />
<child link="segment2" />
<axis xyz="0 0 1"/>
<limit effort="1" velocity="20" />
<joint_properties friction="0.0"/>
</joint>

<joint name="r1" type="revolute">
<origin xyz="-4.3051519674790368049e-17 -0.070436072480308878352 0.061999999999999430567" rpy="-1.570796326794896558 -1.5707963267948954478 0" />
<parent link="base" />
<child link="bras1" />
<axis xyz="0 0 1"/>
<limit effort="1" velocity="20" />
<joint_properties friction="0.0"/>
</joint>


</robot>
