<robot name="onshape">
<link name="base">
<visual>
<origin xyz="-3.1995672897847401109e-16 -0.011036072480300897214 0.061999999999997092159" rpy="-6.1232620554170331445e-17 -1.3270634591222507219e-15 3.141592653589793116" />
<geometry>
<mesh filename="package:///80i_v5.stl"/>
</geometry>
<material name="80i_v5_material">
<color rgba="0.61568627450980395466 0.81176470588235294379 0.92941176470588238168 1.0"/>
</material>
</visual>
<collision>
<origin xyz="-3.1995672897847401109e-16 -0.011036072480300897214 0.061999999999997092159" rpy="-6.1232620554170331445e-17 -1.3270634591222507219e-15 3.141592653589793116" />
<geometry>
<mesh filename="package:///80i_v5.stl"/>
</geometry>
</collision>
<visual>
<origin xyz="-2.6194323913312536696e-16 -0.06093607248030450535 0.0019999999999976260726" rpy="1.1050188541972292746e-15 -6.1232339957368473871e-17 1.570796326794896558" />
<geometry>
<mesh filename="package:///bati_erob80.stl"/>
</geometry>
<material name="bati_erob80_material">
<color rgba="0.47450980392156860699 0.35294117647058825815 0 1.0"/>
</material>
</visual>
<collision>
<origin xyz="-2.6194323913312536696e-16 -0.06093607248030450535 0.0019999999999976260726" rpy="1.1050188541972292746e-15 -6.1232339957368473871e-17 1.570796326794896558" />
<geometry>
<mesh filename="package:///bati_erob80.stl"/>
</geometry>
</collision>
<inertial>
<origin xyz="8.5965635448622304657e-05 -0.028034738804695542858 0.056265374431782332054" rpy="0 0 0"/>
<mass value="2.1622242401867128869" />
<inertia ixx="0.0035409411921381631592" ixy="-1.051535304357034727e-05"  ixz="-2.7906442063382283728e-06" iyy="0.0039888242306756541145" iyz="0.00051286535117853854996" izz="0.0035605287862095916576" />
</inertial>
</link>

<link name="bras1">
<visual>
<origin xyz="-0.12500000000000002776 -3.6112633082917897775e-17 0.016999999999999987343" rpy="1.570796326794896558 5.6920406751767812971e-33 -1.9105225048187323569e-31" />
<geometry>
<mesh filename="package:///bras1.stl"/>
</geometry>
<material name="bras1_material">
<color rgba="0.50196078431372548323 0.50196078431372548323 0.50196078431372548323 1.0"/>
</material>
</visual>
<collision>
<origin xyz="-0.12500000000000002776 -3.6112633082917897775e-17 0.016999999999999987343" rpy="1.570796326794896558 5.6920406751767812971e-33 -1.9105225048187323569e-31" />
<geometry>
<mesh filename="package:///bras1.stl"/>
</geometry>
</collision>
<inertial>
<origin xyz="-0.12500000000000002776 -3.0238172867234776605e-17 0.0075053453515004295293" rpy="0 0 0"/>
<mass value="1.6401618924870366989" />
<inertia ixx="0.0014573357440108673788" ixy="-7.6494749519212700106e-33"  ixz="-2.5929189483419922331e-35" iyy="0.014585620314120818428" iyz="1.067116182273082496e-39" izz="0.015941817470486976255" />
</inertial>
</link>

<link name="segment2">
<visual>
<origin xyz="-1.3720819860076984538e-23 0 0.027500000000004548584" rpy="1.570796326794896558 -4.3011950331735847137e-22 -3.1415926535897926719" />
<geometry>
<mesh filename="package:///bras2.stl"/>
</geometry>
<material name="bras2_material">
<color rgba="0.50196078431372548323 0.50196078431372548323 0.50196078431372548323 1.0"/>
</material>
</visual>
<collision>
<origin xyz="-1.3720819860076984538e-23 0 0.027500000000004548584" rpy="1.570796326794896558 -4.3011950331735847137e-22 -3.1415926535897926719" />
<geometry>
<mesh filename="package:///bras2.stl"/>
</geometry>
</collision>
<visual>
<origin xyz="-2.4651903288156618919e-32 0 0.059400000000008001955" rpy="-1.570796326794896558 -3.8947973516099456757e-38 -3.6977854932234928379e-32" />
<geometry>
<mesh filename="package:///80i_v5.stl"/>
</geometry>
<material name="80i_v5_material">
<color rgba="0.61568627450980395466 0.81176470588235294379 0.92941176470588238168 1.0"/>
</material>
</visual>
<collision>
<origin xyz="-2.4651903288156618919e-32 0 0.059400000000008001955" rpy="-1.570796326794896558 -3.8947973516099456757e-38 -3.6977854932234928379e-32" />
<geometry>
<mesh filename="package:///80i_v5.stl"/>
</geometry>
</collision>
<visual>
<origin xyz="-3.0184188855770821741e-15 -0.24999999999997304934 -0.027499999999995250466" rpy="3.1469101278800308105e-14 1.1129985391747538395e-14 -3.1415926535897926719" />
<geometry>
<mesh filename="package:///weight.stl"/>
</geometry>
<material name="weight_material">
<color rgba="0.30196078431372547213 0.30196078431372547213 0.30196078431372547213 1.0"/>
</material>
</visual>
<collision>
<origin xyz="-3.0184188855770821741e-15 -0.24999999999997304934 -0.027499999999995250466" rpy="3.1469101278800308105e-14 1.1129985391747538395e-14 -3.1415926535897926719" />
<geometry>
<mesh filename="package:///weight.stl"/>
</geometry>
</collision>
<inertial>
<origin xyz="-1.4457205374984982062e-05 -0.20443246054269070822 -0.002384758765795871871" rpy="0 0 0"/>
<mass value="12.857047818015507445" />
<inertia ixx="0.16793351668194522741" ixy="3.9723997859661760871e-05"  ixz="1.8840056687060199848e-05" iyy="0.064620563529158903116" iyz="-0.019837037963190737311" izz="0.22122597307178804016" />
</inertial>
</link>

<link name="end">
<inertial>
<origin xyz="0 0 0" rpy="0 0 0" />
<mass value="1e-9" />
<inertia ixx="0" ixy="0" ixz="0" iyy="0" iyz="0" izz="0" />
</inertial>
</link>
<joint name="end_frame" type="fixed">
<origin xyz="-2.9837244171328454876e-15 -0.24999999999997310485 -0.029999999999995238809" rpy="3.1415926535897820138 3.1469101278800327038e-14 1.5707963267948970021" />
<parent link="segment2" />
<child link="end" />
<axis xyz="0 0 0"/>
</joint>

<joint name="R2" type="revolute">
<origin xyz="-0.25000000000000005551 -4.305149412567801521e-17 -1.3877787807814456755e-17" rpy="-3.141592653589793116 5.0387059551511362915e-28 1.5707963267949036634" />
<parent link="bras1" />
<child link="segment2" />
<axis xyz="0 0 1"/>
<limit effort="1" velocity="20" />
<joint_properties friction="0.0"/>
</joint>

<joint name="R1" type="revolute">
<origin xyz="-4.3051519674790368049e-17 -0.070436072480308878352 0.061999999999999430567" rpy="1.570796326794896558 -1.5707963267948954478 0" />
<parent link="base" />
<child link="bras1" />
<axis xyz="0 0 1"/>
<limit effort="1" velocity="20" />
<joint_properties friction="0.0"/>
</joint>


</robot>
