<robot name="onshape">
<link name="sts32155">
<visual>
<origin xyz="0.009376592002809047699 -0.032150233221054091981 0.019306784727573363114" rpy="0 -0 0" />
<geometry>
<mesh filename="./motor_holder.stl"/>
</geometry>
<material name="motor_holder_material">
<color rgba="0.61568627450980395466 0.81176470588235294379 0.92941176470588238168 1.0"/>
</material>
</visual>
<collision>
<origin xyz="0.009376592002809047699 -0.032150233221054091981 0.019306784727573363114" rpy="0 -0 0" />
<geometry>
<mesh filename="./motor_holder.stl"/>
</geometry>
</collision>
<visual>
<origin xyz="0.009376592002809047699 -0.041750233221054082466 0.044741784727573383207" rpy="-3.1415926535897926719 -1.570796326794896558 0" />
<geometry>
<mesh filename="./wj-wk00-0123middlecase_56.stl"/>
</geometry>
<material name="wj-wk00-0123middlecase_56_material">
<color rgba="0.24705882352941177516 0.24313725490196078094 0.24313725490196078094 1.0"/>
</material>
</visual>
<collision>
<origin xyz="0.009376592002809047699 -0.041750233221054082466 0.044741784727573383207" rpy="-3.1415926535897926719 -1.570796326794896558 0" />
<geometry>
<mesh filename="./wj-wk00-0123middlecase_56.stl"/>
</geometry>
</collision>
<visual>
<origin xyz="0.009376592002809047699 -0.041750233221054082466 0.044741784727573383207" rpy="-3.1415926535897926719 -1.570796326794896558 0" />
<geometry>
<mesh filename="./drive_palonier.stl"/>
</geometry>
<material name="drive_palonier_material">
<color rgba="0.62352941176470588758 0.66666666666666662966 0.70196078431372543882 1.0"/>
</material>
</visual>
<collision>
<origin xyz="0.009376592002809047699 -0.041750233221054082466 0.044741784727573383207" rpy="-3.1415926535897926719 -1.570796326794896558 0" />
<geometry>
<mesh filename="./drive_palonier.stl"/>
</geometry>
</collision>
<visual>
<origin xyz="0.009376592002809047699 -0.041750233221054082466 0.044741784727573383207" rpy="-3.1415926535897926719 -1.570796326794896558 0" />
<geometry>
<mesh filename="./wj-wk00-0124bottomcase_45.stl"/>
</geometry>
<material name="wj-wk00-0124bottomcase_45_material">
<color rgba="0.24705882352941177516 0.24313725490196078094 0.24313725490196078094 1.0"/>
</material>
</visual>
<collision>
<origin xyz="0.009376592002809047699 -0.041750233221054082466 0.044741784727573383207" rpy="-3.1415926535897926719 -1.570796326794896558 0" />
<geometry>
<mesh filename="./wj-wk00-0124bottomcase_45.stl"/>
</geometry>
</collision>
<visual>
<origin xyz="0.009376592002809047699 -0.041750233221054082466 0.044741784727573383207" rpy="-3.1415926535897926719 -1.570796326794896558 0" />
<geometry>
<mesh filename="./wj-wk00-0122topcabinetcase_95.stl"/>
</geometry>
<material name="wj-wk00-0122topcabinetcase_95_material">
<color rgba="0.24705882352941177516 0.24313725490196078094 0.24313725490196078094 1.0"/>
</material>
</visual>
<collision>
<origin xyz="0.009376592002809047699 -0.041750233221054082466 0.044741784727573383207" rpy="-3.1415926535897926719 -1.570796326794896558 0" />
<geometry>
<mesh filename="./wj-wk00-0122topcabinetcase_95.stl"/>
</geometry>
</collision>
<visual>
<origin xyz="0.0093765920028090338212 -0.044650233221054151656 0.044741784727573376268" rpy="-3.1415926535897926719 -1.570796326794896558 0" />
<geometry>
<mesh filename="./passive_palonier.stl"/>
</geometry>
<material name="passive_palonier_material">
<color rgba="0.62352941176470588758 0.66666666666666662966 0.70196078431372543882 1.0"/>
</material>
</visual>
<collision>
<origin xyz="0.0093765920028090338212 -0.044650233221054151656 0.044741784727573376268" rpy="-3.1415926535897926719 -1.570796326794896558 0" />
<geometry>
<mesh filename="./passive_palonier.stl"/>
</geometry>
</collision>
<inertial>
<origin xyz="0.0093734536149213641687 -0.024754451544399275892 0.047619286255456055867" rpy="0 0 0"/>
<mass value="0.11439387461713544647" />
<inertia ixx="9.9457487576317163934e-05" ixy="-5.3739882506932776796e-09"  ixz="-1.3079909721710029822e-08" iyy="5.6552620418519873005e-05" iyz="-1.9820495023056688164e-05" izz="6.1748851992714340635e-05" />
</inertial>
</link>

<link name="right_sheet">
<visual>
<origin xyz="0 6.9388939039072283776e-18 0.019049999999999955858" rpy="1.570796326794896336 4.2415438274104704064e-32 0" />
<geometry>
<mesh filename="./right_sheet.stl"/>
</geometry>
<material name="right_sheet_material">
<color rgba="0.64705882352941179736 0.64705882352941179736 0.64705882352941179736 1.0"/>
</material>
</visual>
<collision>
<origin xyz="0 6.9388939039072283776e-18 0.019049999999999955858" rpy="1.570796326794896336 4.2415438274104704064e-32 0" />
<geometry>
<mesh filename="./right_sheet.stl"/>
</geometry>
</collision>
<visual>
<origin xyz="0 7.6327832942979512154e-17 0.016999999999999765299" rpy="1.570796326794896558 4.2415438274107052333e-32 -3.9443045261050660336e-31" />
<geometry>
<mesh filename="./axle.stl"/>
</geometry>
<material name="axle_material">
<color rgba="0.2313725490196078538 0.38039215686274507888 0.7058823529411765163 1.0"/>
</material>
</visual>
<collision>
<origin xyz="0 7.6327832942979512154e-17 0.016999999999999765299" rpy="1.570796326794896558 4.2415438274107052333e-32 -3.9443045261050660336e-31" />
<geometry>
<mesh filename="./axle.stl"/>
</geometry>
</collision>
<visual>
<origin xyz="1.2143064331837649661e-17 -6.9388939039072283776e-18 0.017299999999999926548" rpy="1.570796326794896558 4.2415438274104704064e-32 0" />
<geometry>
<mesh filename="./weight.stl"/>
</geometry>
<material name="weight_material">
<color rgba="0.97254901960784312376 0.52941176470588235947 0.0039215686274509803377 1.0"/>
</material>
</visual>
<collision>
<origin xyz="1.2143064331837649661e-17 -6.9388939039072283776e-18 0.017299999999999926548" rpy="1.570796326794896558 4.2415438274104704064e-32 0" />
<geometry>
<mesh filename="./weight.stl"/>
</geometry>
</collision>
<visual>
<origin xyz="3.4694469519536141888e-18 -6.9388939039072283776e-18 -0.0069500000000000602962" rpy="1.570796326794896558 4.2415438274104704064e-32 0" />
<geometry>
<mesh filename="./spacer_2.stl"/>
</geometry>
<material name="spacer_2_material">
<color rgba="0.76862745098039220171 0.88627450980392152857 0.95294117647058818044 1.0"/>
</material>
</visual>
<collision>
<origin xyz="3.4694469519536141888e-18 -6.9388939039072283776e-18 -0.0069500000000000602962" rpy="1.570796326794896558 4.2415438274104704064e-32 0" />
<geometry>
<mesh filename="./spacer_2.stl"/>
</geometry>
</collision>
<inertial>
<origin xyz="7.6994893878616468638e-18 0.14678324820460611488 0.0159300425321751149" rpy="0 0 0"/>
<mass value="0.68612173735167969468" />
<inertia ixx="0.0011109350751486632945" ixy="-2.7412883293436491895e-20"  ixz="-1.0216639076881527627e-20" iyy="0.0009077430330042012864" iyz="-4.0622405946211065603e-05" izz="0.0018270911057228227288" />
</inertial>
</link>

<joint name="sts3215" type="revolute">
<origin xyz="0.0093765920028090546379 -0.051200233221054061716 0.019241784727573367497" rpy="-1.570796326794896558 -1.972152263052532141e-31 6.3429678944075910852e-16" />
<parent link="sts32155" />
<child link="right_sheet" />
<axis xyz="0 0 1"/>
<limit effort="1" velocity="20" lower="-1.7453292519943295336" upper="1.7453292519943295336"/>
<joint_properties friction="0.0"/>
</joint>


</robot>
